[2024-11-19T13:26:04.254+0530] {taskinstance.py:1979} INFO - Dependencies all met for dep_context=non-requeueable deps ti=<TaskInstance: toxic_comment_classification.train_model manual__2024-11-19T07:53:47.328440+00:00 [queued]>
[2024-11-19T13:26:04.268+0530] {taskinstance.py:1979} INFO - Dependencies all met for dep_context=requeueable deps ti=<TaskInstance: toxic_comment_classification.train_model manual__2024-11-19T07:53:47.328440+00:00 [queued]>
[2024-11-19T13:26:04.268+0530] {taskinstance.py:2193} INFO - Starting attempt 2 of 2
[2024-11-19T13:26:04.297+0530] {taskinstance.py:2217} INFO - Executing <Task(PythonOperator): train_model> on 2024-11-19 07:53:47.328440+00:00
[2024-11-19T13:26:04.306+0530] {standard_task_runner.py:60} INFO - Started process 36082 to run task
[2024-11-19T13:26:04.316+0530] {standard_task_runner.py:87} INFO - Running: ['airflow', 'tasks', 'run', 'toxic_comment_classification', 'train_model', 'manual__2024-11-19T07:53:47.328440+00:00', '--job-id', '23', '--raw', '--subdir', 'DAGS_FOLDER/ml_workflow_dag.py', '--cfg-path', '/tmp/tmp0gx5abig']
[2024-11-19T13:26:04.318+0530] {standard_task_runner.py:88} INFO - Job 23: Subtask train_model
[2024-11-19T13:26:04.399+0530] {task_command.py:423} INFO - Running <TaskInstance: toxic_comment_classification.train_model manual__2024-11-19T07:53:47.328440+00:00 [running]> on host sigmoid-ThinkPad-L470-W10DG
[2024-11-19T13:26:04.519+0530] {taskinstance.py:2513} INFO - Exporting env vars: AIRFLOW_CTX_DAG_OWNER='airflow' AIRFLOW_CTX_DAG_ID='toxic_comment_classification' AIRFLOW_CTX_TASK_ID='train_model' AIRFLOW_CTX_EXECUTION_DATE='2024-11-19T07:53:47.328440+00:00' AIRFLOW_CTX_TRY_NUMBER='2' AIRFLOW_CTX_DAG_RUN_ID='manual__2024-11-19T07:53:47.328440+00:00'
[2024-11-19T13:26:04.523+0530] {taskinstance.py:2731} ERROR - Task failed with exception
Traceback (most recent call last):
  File "/home/sigmoid/Desktop/Personal_Ml/airflow_poc/airflow_env/lib/python3.8/site-packages/airflow/models/taskinstance.py", line 444, in _execute_task
    result = _execute_callable(context=context, **execute_callable_kwargs)
  File "/home/sigmoid/Desktop/Personal_Ml/airflow_poc/airflow_env/lib/python3.8/site-packages/airflow/models/taskinstance.py", line 414, in _execute_callable
    return execute_callable(context=context, **execute_callable_kwargs)
  File "/home/sigmoid/Desktop/Personal_Ml/airflow_poc/airflow_env/lib/python3.8/site-packages/airflow/operators/python.py", line 200, in execute
    return_value = self.execute_callable()
  File "/home/sigmoid/Desktop/Personal_Ml/airflow_poc/airflow_env/lib/python3.8/site-packages/airflow/operators/python.py", line 217, in execute_callable
    return self.python_callable(*self.op_args, **self.op_kwargs)
  File "/home/sigmoid/airflow/dags/ml_workflow_dag.py", line 74, in train_model
    X, y = data_original()
  File "/home/sigmoid/airflow/dags/ml_workflow_dag.py", line 44, in data_original
    data = pd.read_csv('train.csv')
  File "/home/sigmoid/Desktop/Personal_Ml/airflow_poc/airflow_env/lib/python3.8/site-packages/pandas/io/parsers/readers.py", line 912, in read_csv
    return _read(filepath_or_buffer, kwds)
  File "/home/sigmoid/Desktop/Personal_Ml/airflow_poc/airflow_env/lib/python3.8/site-packages/pandas/io/parsers/readers.py", line 577, in _read
    parser = TextFileReader(filepath_or_buffer, **kwds)
  File "/home/sigmoid/Desktop/Personal_Ml/airflow_poc/airflow_env/lib/python3.8/site-packages/pandas/io/parsers/readers.py", line 1407, in __init__
    self._engine = self._make_engine(f, self.engine)
  File "/home/sigmoid/Desktop/Personal_Ml/airflow_poc/airflow_env/lib/python3.8/site-packages/pandas/io/parsers/readers.py", line 1661, in _make_engine
    self.handles = get_handle(
  File "/home/sigmoid/Desktop/Personal_Ml/airflow_poc/airflow_env/lib/python3.8/site-packages/pandas/io/common.py", line 859, in get_handle
    handle = open(
FileNotFoundError: [Errno 2] No such file or directory: 'train.csv'
[2024-11-19T13:26:04.536+0530] {taskinstance.py:1149} INFO - Marking task as FAILED. dag_id=toxic_comment_classification, task_id=train_model, execution_date=20241119T075347, start_date=20241119T075604, end_date=20241119T075604
[2024-11-19T13:26:04.557+0530] {standard_task_runner.py:107} ERROR - Failed to execute job 23 for task train_model ([Errno 2] No such file or directory: 'train.csv'; 36082)
[2024-11-19T13:26:04.609+0530] {local_task_job_runner.py:234} INFO - Task exited with return code 1
[2024-11-19T13:26:04.629+0530] {taskinstance.py:3312} INFO - 0 downstream tasks scheduled from follow-on schedule check
